Workbook
Name Slicer_Store_Name_Region: #N/A

Sheet Customer_Dim
A1: Customer_ID | B1: Name | C1: Age | D1: Gender | E1: City | F1: State | G1: Country | H1: Loyalty_Level
A2: CUST1000 | B2: Sheena Bonilla | C2: 55 | D2: Male | E2: Donaldton | F2: North Carolina | G2: USA | H2: Unknown
A3: CUST1001 | B3: Eugene Nelson | C3: 26 | D3: Female | E3: Phillipsmouth | F3: North Dakota | G3: USA | H3: Platinum | J3: Highlight Cell Rules:Above 30 years of age is highlighted using highlight cell rules.
A4: CUST1002 | B4: Dr. Benjamin Price | C4: 29 | D4: Female | E4: Kylebury | F4: Alabama | G4: USA | H4: Platinum
A5: CUST1003 | B5: Jeremy Harris | C5: 59 | D5: Female | E5: Thomastown | F5: Ohio | G5: USA | H5: Bronze
A6: CUST1004 | B6: Caroline Collins | C6: 64 | D6: Female | E6: Nicholasshire | F6: California | G6: USA | H6: Silver
A7: CUST1005 | B7: Christine Vaughn | C7: 24 | D7: Male | E7: East Amandamouth | F7: Oregon | G7: USA | H7: Bronze
A8: CUST1006 | B8: Amber Jackson | C8: 29 | D8: Female | E8: Deborahborough | F8: South Dakota | G8: USA | H8: Platinum
A9: CUST1007 | B9: Daniel Boyd | C9: 29 | D9: Female | E9: West Pamelafurt | F9: West Virginia | G9: USA | H9: Bronze
A10: CUST1008 | B10: Melissa Howard | C10: 53 | D10: Female | E10: Maynardton | F10: New Hampshire | G10: USA | H10: Gold
A11: CUST1009 | B11: Ms. Maria Leach | C11: 64 | D11: Male | E11: Melissashire | F11: Pennsylvania | G11: USA | H11: Platinum
A12: CUST1010 | B12: Dominic Page | C12: 53 | D12: Male | E12: Port Michaelburgh | F12: Pennsylvania | G12: USA | H12: Bronze
A13: CUST1011 | B13: Brian Lopez | C13: 28 | D13: Female | E13: East Krista | F13: New York | G13: USA | H13: Gold
A14: CUST1012 | B14: Kenneth Lambert | C14: 55 | D14: Female | E14: North Kathryn | F14: Kansas | G14: USA | H14: Platinum
A15: CUST1013 | B15: Nathan Hernandez | C15: 32 | D15: Female | E15: New Becky | F15: Montana | G15: USA | H15: Silver
... A501: CUST1499 | B501: Philip Pennington | C501: 27 | D501: Female | E501: East Valerieview | F501: Oregon | G501: USA | H501: Platinum

Sheet Product_Dim
A1: Product_ID | B1: Product Name with category | C1: Sub_Category | D1: Brand | E1: Cost | F1: Stock range | G1: Stock Value
A2: PROD0 | B2: Brother Laser Printer-Electronics | C2: Computer | D2: Hunt Inc | E2: 112.42 | F2: =IF(Table2[[#This Row],[Stock Value]]>200,"High","Low") -> High | G2: 416
A3: PROD1 | B3: Men's Graphic T-Shirt-Clothing | C3: Tops | D3: Terry-Moore | E3: 342.56 | F3: =IF(Table2[[#This Row],[Stock Value]]>200,"High","Low") -> Low | G3: 181 | I3: IF function:
A4: PROD2 | B4: Women's Casual Hoodie-Clothing | C4: Outerwear | D4: Sims Inc | E4: 254.62087 | F4: =IF(Table2[[#This Row],[Stock Value]]>200,"High","Low") -> High | G4: 352 | I4: IF(G2>200,"High","Low")
A5: PROD3 | B5: Men's Running Jacket-Clothing | C5: Outerwear | D5: Pineda Ltd | E5: 364.67 | F5: =IF(Table2[[#This Row],[Stock Value]]>200,"High","Low") -> High | G5: 452 | I5: Color bars are applied based on the price range.
A6: PROD4 | B6: Women's Yoga Pants-Clothing | C6: Bottoms | D6: Gonzales-Davis | E6: 306.46 | F6: =IF(Table2[[#This Row],[Stock Value]]>200,"High","Low") -> High | G6: 487 | I6: SUMIF Function: | K6: Cost in accessories sub category is added.
A7: PROD5 | B7: Men's Leather Belt-Clothing | C7: Accessories | D7: Baldwin, Garza and Gonzalez | E7: 261 | F7: =IF(Table2[[#This Row],[Stock Value]]>200,"High","Low") -> Low | G7: 59 | I7: Formula used: | K7: SUMIF(C2:C101,C7,E2:E101)
A8: PROD6 | B8: Herbal Face Moisturizer-Beauty | C8: Skincare | D8: Davidson PLC | E8: 312.8 | F8: =IF(Table2[[#This Row],[Stock Value]]>200,"High","Low") -> High | G8: 350 | I8: =SUMIF(C2:C101,C13,E2:E101) -> 3708.07
A9: PROD7 | B9: LED Table Lamp-Home | C9: Lighting | D9: Harrell LLC | E9: 218.86 | F9: =IF(Table2[[#This Row],[Stock Value]]>200,"High","Low") -> Low | G9: 170
A10: PROD8 | B10: Wireless Bluetooth Earbuds-Electronics | C10: Audio | D10: Perez-Johnston | E10: 439.07 | F10: =IF(Table2[[#This Row],[Stock Value]]>200,"High","Low") -> Low | G10: 142
A11: PROD9 | B11: Adjustable Dumbbell Set-Sports | C11: Fitness | D11: Hill PLC | E11: 495.72 | F11: =IF(Table2[[#This Row],[Stock Value]]>200,"High","Low") -> High | G11: 323
A12: PROD10 | B12: Ceramic Kitchen Bowl Set-Home | C12: Kitchen | D12: Hamilton Group | E12: 298.86 | F12: =IF(Table2[[#This Row],[Stock Value]]>200,"High","Low") -> High | G12: 308
A13: PROD11 | B13: HD Smart TV Stick-Electronics | C13: Accessories | D13: Gibson, Hobbs and Weaver | E13: 449.4 | F13: =IF(Table2[[#This Row],[Stock Value]]>200,"High","Low") -> High | G13: 270.80233
A14: PROD12 | B14: Hair Strengthening Shampoo-Beauty | C14: Haircare | D14: Rice LLC | E14: 115.82 | F14: =IF(Table2[[#This Row],[Stock Value]]>200,"High","Low") -> High | G14: 460
A15: PROD13 | B15: USB-C Fast Charger-Electronics | C15: Accessories | D15: Dawson-Perkins | E15: 242.23 | F15: =IF(Table2[[#This Row],[Stock Value]]>200,"High","Low") -> High | G15: 453
A16: PROD14 | B16: Decorative Wall Mirror-Home | C16: Decor | D16: Luna, Anderson and Bowman | E16: 48.01 | F16: =IF(Table2[[#This Row],[Stock Value]]>200,"High","Low") -> High | G16: 439
A17: PROD15 | B17: 4K Home Projector-Electronics | C17: Appliances | D17: Thomas LLC | E17: 465.34 | F17: =IF(Table2[[#This Row],[Stock Value]]>200,"High","Low") -> High | G17: 301
A18: PROD16 | B18: Beard Grooming Kit-Beauty | C18: Grooming | D18: Erickson-Green | E18: 337.42 | F18: =IF(Table2[[#This Row],[Stock Value]]>200,"High","Low") -> High | G18: 256
A19: PROD17 | B19: Soccer Training Cone Set-Sports | C19: Accessories | D19: Ford, Murphy and Wilson | E19: 144.53 | F19: =IF(Table2[[#This Row],[Stock Value]]>200,"High","Low") -> High | G19: 367
A20: PROD18 | B20: Women's Denim Jeans-Clothing | C20: Bottoms | D20: Guerra-Hendrix | E20: 245.77831 | F20: =IF(Table2[[#This Row],[Stock Value]]>200,"High","Low") -> High | G20: 343
... A101: PROD99 | B101: Stainless Steel Cookware Set-Home | C101: Kitchen | D101: Campbell Ltd | E101: 201.41 | F101: =IF(Table2[[#This Row],[Stock Value]]>200,"High","Low") -> Low | G101: 146

Sheet Store_Dim
A1: Column1 | B1: Column12 | C1: Column5 | D1: Column6
A2: Store_ID | B2: Store_Name-Region | C2: City | D2: Store_Type
A3: STORE0 | B3: Rivera-Warner-East | C3: Washingtonfurt | D3: Flagship
A4: STORE1 | B4: Martinez, Adkins and Johnson-North | C4: Danielmouth | D4: Flagship
A5: STORE2 | B5: Black-Horn-South | C5: North Nancyview | D5: Outlet
A6: STORE3 | B6: Johnson-Wright-North | C6: Hoodberg | D6: Outlet
A7: STORE4 | B7: Alexander Group-South | C7: Port Sharon | D7: Online
A8: STORE5 | B8: Gray Ltd-North | C8: New Michaelchester | D8: Outlet
A9: STORE6 | B9: Benson-Elliott-East | C9: Port Josephberg | D9: Online
A10: STORE7 | B10: Martinez-Mullins-South | C10: Williamsfurt | D10: Online
A11: STORE8 | B11: Bean, Jones and Park-West | C11: Thompsonborough | D11: Online
A12: STORE9 | B12: Moore, Padilla and Butler-South | C12: East Johnstad | D12: Flagship
... A22: STORE19 | B22: Mann-Austin-East | C22: Vasquezborough | D22: Online

Sheet Region -yearwise
A3: Sum of Total_amount | B3: Column Labels
A4: Row Labels | B4: Aguirre-Keller-South | C4: Alexander Group-South | D4: Bean, Jones and Park-West | E4: Benson-Elliott-East | F4: Black-Horn-South | G4: Frederick-Wright-West | H4: Gardner, Humphrey and Contreras-East | I4: Gray Ltd-North | J4: Guerrero-Schmitt-East | K4: Holloway Ltd-North | L4: Mcdonald Inc-South | M4: Moore, Padilla and Butler-South | N4: Rivera-Warner-East | O4: Shelton PLC-North | P4: Thomas, Bridges and Harris-North | Q4: Grand Total
A5: 2023 | B5: 4958.7861 | C5: 12055.56 | D5: 15838.583 | E5: 17550.365 | F5: 14092.537 | G5: 2266.0419 | H5: 10046.363 | I5: 10700.706 | J5: 10834.37 | K5: 12814.569 | L5: 5524.3127 | M5: 3793.6722 | N5: 9046.0773 | O5: 12964.754 | P5: 8439.0101 | Q5: 150925.71
A6: 2024 | B6: 54325.894 | C6: 63483.123 | D6: 64837.021 | E6: 49290.706 | F6: 46410.977 | G6: 66040.747 | H6: 52349.374 | I6: 42798.136 | J6: 46461.761 | K6: 67829.833 | L6: 57066.414 | M6: 63351.601 | N6: 33962.257 | O6: 54110.989 | P6: 62045.402 | Q6: 824364.24
A7: 2025 | B7: 33763.46 | C7: 43275.432 | D7: 78295.859 | E7: 47692.726 | F7: 38457.294 | G7: 43398.155 | H7: 52005.734 | I7: 28733.507 | J7: 47016.923 | K7: 41887.31 | L7: 43657.557 | M7: 42957.125 | N7: 42130.221 | O7: 32603.344 | P7: 46344.808 | Q7: 662219.46
A8: Grand Total | B8: 93048.141 | C8: 118814.12 | D8: 158971.46 | E8: 114533.8 | F8: 98960.808 | G8: 111704.94 | H8: 114401.47 | I8: 82232.348 | J8: 104313.05 | K8: 122531.71 | L8: 106248.28 | M8: 110102.4 | N8: 85138.555 | O8: 99679.086 | P8: 116829.22 | Q8: 1637509.4

Sheet Monthwise
A3: Sum of Total_amount | B3: Column Labels
A4: Row Labels | B4: 2023 | C4: 2024 | D4: 2025 | E4: Grand Total
A5: April | C5: 4889.3898 | D5: 6057.9152 | E5: 10947.305
A6: August | C6: 3410.4235 | D6: 1511.3323 | E6: 4921.7558
A7: December | B7: 1139.2544 | C7: 5384.6058 | E7: 6523.8602
A8: February | C8: 3561.8304 | D8: 1034.7036 | E8: 4596.534
A9: January | C9: 3271.7152 | D9: 10234.723 | E9: 13506.438
A10: July | C10: 4931.665 | D10: 3308.796 | E10: 8240.461
A11: June | C11: 3819.8173 | E11: 3819.8173
A12: March | C12: 2691.3326 | D12: 4921.7572 | E12: 7613.0898
A13: May | C13: 4006.7943 | D13: 4045.018 | E13: 8051.8123
A14: November | B14: 2638.8927 | C14: 5205.7253 | E14: 7844.618
A15: October | B15: 1180.639 | C15: 5455.2694 | D15: 2017.5012 | E15: 8653.4096
A16: September | C16: 7697.3256 | D16: 631.7138 | E16: 8329.0394
A17: Grand Total | B17: 4958.7861 | C17: 54325.894 | D17: 33763.46 | E17: 93048.141
F21: Total amount is calculated for different months with respective year.Slicers is applied for Aguirre-keller-south region and | K21: column chart is applied for analysis.
G22: X-axis-Month
G23: Y-axis-Total Amount

Sheet Category Wise
A3: Row Labels | B3: Sum of Total_amount
A4: Makeup Brush Set-Beauty | B4: 7948.3905
A5: Vitamin C Face Serum-Beauty | B5: 9681.9319
A6: Herbal Face Moisturizer-Beauty | B6: 9937.0898 | D6: Total Amount for different categories is calculated for this dataset.
A7: Gaming Mouse Pad XL-Electronics | B7: 12127.249
A8: Sports Stopwatch Basic-Sports | B8: 12301.164
A9: Fabric Sofa Throw Blanket-Home | B9: 12665.901
A10: Men's Formal Shirt-Clothing | B10: 12949.499
A11: Adjustable Dumbbell Set-Sports | B11: 13115.581
A12: Rugby Ball-Sports | B12: 13834.392
A13: Stainless Steel Cutlery Set-Home | B13: 14029.913
A14: Adjustable Jump Rope-Sports | B14: 14177.224
A15: Men's Track Pants-Clothing | B15: 14300.937
A16: Women's Denim Jeans-Clothing | B16: 15084.944
A17: Sports Stopwatch Timer-Sports | B17: 15145.865
A18: Women's Summer Dress-Clothing | B18: 15635.99
... A104: Grand Total | B104: 2175265

Sheet Region Wise
A3: Row Labels | B3: Sum of Total_amount | C3: Count of Quantity
A4: Aguirre-Keller-South | B4: 93048.141 | C4: 88
A5: Alexander Group-South | B5: 118814.12 | C5: 102
A6: Bean, Jones and Park-West | B6: 158971.46 | C6: 127
A7: Benson-Elliott-East | B7: 114533.8 | C7: 106
A8: Black-Horn-South | B8: 98960.808 | C8: 92
A9: Frederick-Wright-West | B9: 111704.94 | C9: 106
A10: Gardner, Humphrey and Contreras-East | B10: 114401.47 | C10: 95
A11: Gray Ltd-North | B11: 82232.348 | C11: 83
A12: Guerrero-Schmitt-East | B12: 104313.05 | C12: 105
A13: Hill, Wagner and Ballard-East | B13: 109454.57 | C13: 97
A14: Holloway Ltd-North | B14: 122531.71 | C14: 110
A15: Johnson-Wright-North | B15: 125011.83 | C15: 114
... A20: Moore, Padilla and Butler-South | B20: 110102.4 | C20: 96
A21: Rivera-Warner-East | B21: 85138.555 | C21: 93 | F21: Regionwise sales for different regions is calculated using Line chart
A22: Shelton PLC-North | B22: 99679.086 | C22: 95 | F22: X-axis-Sum of total amount,count of quantity
A23: Thomas, Bridges and Harris-North | B23: 116829.22 | C23: 100 | F23: Y-axis-Store name-region
A24: Grand Total | B24: 2175265 | C24: 2000

Sheet payment mode
A3: Sum of Total_amount | B3: Column Labels
A4: Row Labels | B4: 2023 | C4: 2024 | D4: 2025 | E4: Grand Total
A5: COD | B5: 67845.315 | C5: 358305.66 | D5: 277552.36 | E5: 703703.34
A6: Credit Card | B6: 84467.031 | C6: 319429.08 | D6: 310947.46 | E6: 714843.57
A7: PayPal | B7: 71855.543 | C7: 416140.58 | D7: 268721.98 | E7: 756718.1
A8: Grand Total | B8: 224167.89 | C8: 1093875.3 | D8: 857221.8 | E8: 2175265
A12: Pie chart is created for payment type with respective sum of total amount
A13: From this chart,most of payment done with credit card type.

Sheet Quarter Wise
A3: Row Labels | B3: Sum of Total_amount
A4: Q1 | B4: 540227.6
A5: Q2 | B5: 502016.01
A6: Q3 | B6: 575956.87
A7: Q4 | B7: 557064.52
A8: Grand Total | B8: 2175265
A10: Sum of total amount is calculated for different quarters.From this Quarter-4 has higher amount of sales.

Sheet Sales_Fact
A1: Sales_ID | B1: Quarter | C1: Month | D1: Year | E1: Order_Date | F1: Customer Name | G1: Customer City | H1: Customer_ID | I1: Product name with category | J1: Product_ID | K1: Store_Name-Region | L1: Store_ID | M1: Quantity | N1: Unit_Price | O1: Discount | P1: Payment_Type | Q1: Total_amount
A2: SALE0 | B2: ="Q" &ROUNDUP(MONTH(E2)/3,0) -> Q3 | C2: =TEXT(Table1[[#This Row],[Order_Date]],"mmmm") -> July | D2: =YEAR(Table1[[#This Row],[Order_Date]]) -> 2024 | E2: 45480 | F2: =VLOOKUP(Table1[[#This Row],[Customer_ID]],Customer_Dim!$A$2:$H$501,2,FALSE) -> Sarah Smith | G2: =_xlfn.XLOOKUP(Table1[[#This Row],[Customer_ID]],Customer_Dim!$A$2:$A$501,Customer_Dim!$E$2:$E$501) -> Kathleenport | H2: CUST1409 | I2: =VLOOKUP(Table1[[#This Row],[Product_ID]],Product_Dim!$A$2:$G$101,2,FALSE) -> Cricket Bat-Sports | J2: PROD97 | K2: =VLOOKUP(Table1[[#This Row],[Store_ID]],Store_Dim!$A$3:$D$22,2,FALSE) -> Johnson-Wright-North | L2: STORE3 | M2: 1 | N2: 218.04 | O2: 0.09 | P2: Credit Card | Q2: 198.4164
A3: SALE1 | B3: ="Q" &ROUNDUP(MONTH(E3)/3,0) -> Q4 | C3: =TEXT(Table1[[#This Row],[Order_Date]],"mmmm") -> December | D3: =YEAR(Table1[[#This Row],[Order_Date]]) -> 2023 | E3: 45285 | F3: =VLOOKUP(Table1[[#This Row],[Customer_ID]],Customer_Dim!$A$2:$H$501,2,FALSE) -> Michael Foley | G3: =_xlfn.XLOOKUP(Table1[[#This Row],[Customer_ID]],Customer_Dim!$A$2:$A$501,Customer_Dim!$E$2:$E$501) -> Oneillfurt | H3: CUST1467 | I3: =VLOOKUP(Table1[[#This Row],[Product_ID]],Product_Dim!$A$2:$G$101,2,FALSE) -> Bluetooth Car Audio System-Electronics | J3: PROD74 | K3: =VLOOKUP(Table1[[#This Row],[Store_ID]],Store_Dim!$A$3:$D$22,2,FALSE) -> Holloway Ltd-North | L3: STORE17 | M3: 1 | N3: 104.47 | O3: 0.27 | P3: PayPal | Q3: 228.7893 | V3: Sum | W3: =SUM(Q2:Q2001) -> 2175265
A4: SALE2 | B4: ="Q" &ROUNDUP(MONTH(E4)/3,0) -> Q2 | C4: =TEXT(Table1[[#This Row],[Order_Date]],"mmmm") -> June | D4: =YEAR(Table1[[#This Row],[Order_Date]]) -> 2024 | E4: 45446 | F4: =VLOOKUP(Table1[[#This Row],[Customer_ID]],Customer_Dim!$A$2:$H$501,2,FALSE) -> Christopher Sutton | G4: =_xlfn.XLOOKUP(Table1[[#This Row],[Customer_ID]],Customer_Dim!$A$2:$A$501,Customer_Dim!$E$2:$E$501) -> Deborahberg | H4: CUST1056 | I4: =VLOOKUP(Table1[[#This Row],[Product_ID]],Product_Dim!$A$2:$G$101,2,FALSE) -> Men's Roll-On Perfume-Beauty | J4: PROD49 | K4: =VLOOKUP(Table1[[#This Row],[Store_ID]],Store_Dim!$A$3:$D$22,2,FALSE) -> Bean, Jones and Park-West | L4: STORE8 | M4: 1 | N4: 914.05 | O4: 0.25 | P4: Credit Card | Q4: 2742.15 | V4: Average | W4: =W3/2000 -> 1087.6325
A5: SALE3 | B5: ="Q" &ROUNDUP(MONTH(E5)/3,0) -> Q4 | C5: =TEXT(Table1[[#This Row],[Order_Date]],"mmmm") -> November | D5: =YEAR(Table1[[#This Row],[Order_Date]]) -> 2023 | E5: 45259 | F5: =VLOOKUP(Table1[[#This Row],[Customer_ID]],Customer_Dim!$A$2:$H$501,2,FALSE) -> John Jordan | G5: =_xlfn.XLOOKUP(Table1[[#This Row],[Customer_ID]],Customer_Dim!$A$2:$A$501,Customer_Dim!$E$2:$E$501) -> Port Crystalberg | H5: CUST1346 | I5: =VLOOKUP(Table1[[#This Row],[Product_ID]],Product_Dim!$A$2:$G$101,2,FALSE) -> Wireless Mouse-Electronics | J5: PROD76 | K5: =VLOOKUP(Table1[[#This Row],[Store_ID]],Store_Dim!$A$3:$D$22,2,FALSE) -> Bean, Jones and Park-West | L5: STORE8 | M5: 1 | N5: 921.51 | O5: 0.16 | P5: COD | Q5: 774.0684
A6: SALE4 | B6: ="Q" &ROUNDUP(MONTH(E6)/3,0) -> Q1 | C6: =TEXT(Table1[[#This Row],[Order_Date]],"mmmm") -> January | D6: =YEAR(Table1[[#This Row],[Order_Date]]) -> 2024 | E6: 45297 | F6: =VLOOKUP(Table1[[#This Row],[Customer_ID]],Customer_Dim!$A$2:$H$501,2,FALSE) -> Amanda Powell | G6: =_xlfn.XLOOKUP(Table1[[#This Row],[Customer_ID]],Customer_Dim!$A$2:$A$501,Customer_Dim!$E$2:$E$501) -> South William | H6: CUST1493 | I6: =VLOOKUP(Table1[[#This Row],[Product_ID]],Product_Dim!$A$2:$G$101,2,FALSE) -> Men's Hair Styling Gel-Beauty | J6: PROD59 | K6: =VLOOKUP(Table1[[#This Row],[Store_ID]],Store_Dim!$A$3:$D$22,2,FALSE) -> Gray Ltd-North | L6: STORE5 | M6: 1 | N6: 745.3 | O6: 0.18 | P6: Credit Card | Q6: 1833.438 | V6: Analysis Toolpak
A7: SALE5 | B7: ="Q" &ROUNDUP(MONTH(E7)/3,0) -> Q3 | C7: =TEXT(Table1[[#This Row],[Order_Date]],"mmmm") -> July | D7: =YEAR(Table1[[#This Row],[Order_Date]]) -> 2024 | E7: 45499 | F7: =VLOOKUP(Table1[[#This Row],[Customer_ID]],Customer_Dim!$A$2:$H$501,2,FALSE) -> Anthony Phillips | G7: =_xlfn.XLOOKUP(Table1[[#This Row],[Customer_ID]],Customer_Dim!$A$2:$A$501,Customer_Dim!$E$2:$E$501) -> North Davidport | H7: CUST1116 | I7: =VLOOKUP(Table1[[#This Row],[Product_ID]],Product_Dim!$A$2:$G$101,2,FALSE) -> 4K Home Projector-Electronics | J7: PROD15 | K7: =VLOOKUP(Table1[[#This Row],[Store_ID]],Store_Dim!$A$3:$D$22,2,FALSE) -> Martinez-Mullins-South | L7: STORE7 | M7: 1 | N7: 147.01 | O7: 0.19 | P7: COD | Q7: 357.2343
A8: SALE6 | B8: ="Q" &ROUNDUP(MONTH(E8)/3,0) -> Q3 | C8: =TEXT(Table1[[#This Row],[Order_Date]],"mmmm") -> July | D8: =YEAR(Table1[[#This Row],[Order_Date]]) -> 2025 | E8: 45850 | F8: =VLOOKUP(Table1[[#This Row],[Customer_ID]],Customer_Dim!$A$2:$H$501,2,FALSE) -> John Scott | G8: =_xlfn.XLOOKUP(Table1[[#This Row],[Customer_ID]],Customer_Dim!$A$2:$A$501,Customer_Dim!$E$2:$E$501) -> South Christopher | H8: CUST1016 | I8: =VLOOKUP(Table1[[#This Row],[Product_ID]],Product_Dim!$A$2:$G$101,2,FALSE) -> Premium Blanket Throw-Home | J8: PROD56 | K8: =VLOOKUP(Table1[[#This Row],[Store_ID]],Store_Dim!$A$3:$D$22,2,FALSE) -> Alexander Group-South | L8: STORE4 | M8: 1 | N8: 785.31 | O8: 0.15 | P8: PayPal | Q8: 1335.027 | W8: Mean | X8: 1088.0773
A9: SALE7 | B9: ="Q" &ROUNDUP(MONTH(E9)/3,0) -> Q4 | C9: =TEXT(Table1[[#This Row],[Order_Date]],"mmmm") -> November | D9: =YEAR(Table1[[#This Row],[Order_Date]]) -> 2023 | E9: 45248 | F9: =VLOOKUP(Table1[[#This Row],[Customer_ID]],Customer_Dim!$A$2:$H$501,2,FALSE) -> Patrick Roberts | G9: =_xlfn.XLOOKUP(Table1[[#This Row],[Customer_ID]],Customer_Dim!$A$2:$A$501,Customer_Dim!$E$2:$E$501) -> Jaredville | H9: CUST1152 | I9: =VLOOKUP(Table1[[#This Row],[Product_ID]],Product_Dim!$A$2:$G$101,2,FALSE) -> Kitchen Storage Rack-Home | J9: PROD70 | K9: =VLOOKUP(Table1[[#This Row],[Store_ID]],Store_Dim!$A$3:$D$22,2,FALSE) -> Bean, Jones and Park-West | L9: STORE8 | M9: 1 | N9: 342.39 | O9: 0.23 | P9: PayPal | Q9: 1054.5612 | W9: Standard Error | X9: 18.323976
A10: SALE8 | B10: ="Q" &ROUNDUP(MONTH(E10)/3,0) -> Q2 | C10: =TEXT(Table1[[#This Row],[Order_Date]],"mmmm") -> May | D10: =YEAR(Table1[[#This Row],[Order_Date]]) -> 2025 | E10: 45781 | F10: =VLOOKUP(Table1[[#This Row],[Customer_ID]],Customer_Dim!$A$2:$H$501,2,FALSE) -> Dr. Suzanne Bullock | G10: =_xlfn.XLOOKUP(Table1[[#This Row],[Customer_ID]],Customer_Dim!$A$2:$A$501,Customer_Dim!$E$2:$E$501) -> Lake Blaketon | H10: CUST1187 | I10: =VLOOKUP(Table1[[#This Row],[Product_ID]],Product_Dim!$A$2:$G$101,2,FALSE) -> Stainless Steel Cookware Set-Home | J10: PROD99 | K10: =VLOOKUP(Table1[[#This Row],[Store_ID]],Store_Dim!$A$3:$D$22,2,FALSE) -> Gray Ltd-North | L10: STORE5 | M10: 1 | N10: 448.25 | O10: 0.07 | P10: PayPal | Q10: 1250.6175 | W10: Median | X10: 871.4193
A11: SALE9 | B11: ="Q" &ROUNDUP(MONTH(E11)/3,0) -> Q3 | C11: =TEXT(Table1[[#This Row],[Order_Date]],"mmmm") -> July | D11: =YEAR(Table1[[#This Row],[Order_Date]]) -> 2025 | E11: 45869 | F11: Unknown | G11: Unknown | H11: CUST1464 | I11: =VLOOKUP(Table1[[#This Row],[Product_ID]],Product_Dim!$A$2:$G$101,2,FALSE) -> Modern Wall Clock-Home | J11: PROD33 | K11: =VLOOKUP(Table1[[#This Row],[Store_ID]],Store_Dim!$A$3:$D$22,2,FALSE) -> Rivera-Warner-East | L11: STORE0 | M11: 1 | N11: 873.17 | O11: 0.23 | P11: PayPal | Q11: 1344.6818 | W11: Mode | X11: #N/A
A12: SALE10 | B12: ="Q" &ROUNDUP(MONTH(E12)/3,0) -> Q1 | C12: =TEXT(Table1[[#This Row],[Order_Date]],"mmmm") -> February | D12: =YEAR(Table1[[#This Row],[Order_Date]]) -> 2024 | E12: 45335 | F12: =VLOOKUP(Table1[[#This Row],[Customer_ID]],Customer_Dim!$A$2:$H$501,2,FALSE) -> Michael Thomas | G12: =_xlfn.XLOOKUP(Table1[[#This Row],[Customer_ID]],Customer_Dim!$A$2:$A$501,Customer_Dim!$E$2:$E$501) -> Woodmouth | H12: CUST1065 | I12: =VLOOKUP(Table1[[#This Row],[Product_ID]],Product_Dim!$A$2:$G$101,2,FALSE) -> Foldable Camping Chair-Sports | J12: PROD24 | K12: =VLOOKUP(Table1[[#This Row],[Store_ID]],Store_Dim!$A$3:$D$22,2,FALSE) -> Mcdonald Inc-South | L12: STORE14 | M12: 1 | N12: 278.63 | O12: 0.07 | P12: Credit Card | Q12: 259.1259 | W12: Standard Deviation | X12: 819.26822
A13: SALE11 | B13: ="Q" &ROUNDUP(MONTH(E13)/3,0) -> Q2 | C13: =TEXT(Table1[[#This Row],[Order_Date]],"mmmm") -> May | D13: =YEAR(Table1[[#This Row],[Order_Date]]) -> 2025 | E13: 45801 | F13: =VLOOKUP(Table1[[#This Row],[Customer_ID]],Customer_Dim!$A$2:$H$501,2,FALSE) -> Jessica Gonzalez | G13: =_xlfn.XLOOKUP(Table1[[#This Row],[Customer_ID]],Customer_Dim!$A$2:$A$501,Customer_Dim!$E$2:$E$501) -> South Darrenland | H13: CUST1320 | I13: =VLOOKUP(Table1[[#This Row],[Product_ID]],Product_Dim!$A$2:$G$101,2,FALSE) -> Portable Power Bank-Electronics | J13: PROD39 | K13: =VLOOKUP(Table1[[#This Row],[Store_ID]],Store_Dim!$A$3:$D$22,2,FALSE) -> Martinez, Adkins and Johnson-North | L13: STORE1 | M13: 1 | N13: 286.92 | O13: 0.17 | P13: Credit Card | Q13: 952.5744 | W13: Sample Variance | X13: 671200.41
A14: SALE12 | B14: ="Q" &ROUNDUP(MONTH(E14)/3,0) -> Q3 | C14: =TEXT(Table1[[#This Row],[Order_Date]],"mmmm") -> August | D14: =YEAR(Table1[[#This Row],[Order_Date]]) -> 2024 | E14: 45528 | F14: =VLOOKUP(Table1[[#This Row],[Customer_ID]],Customer_Dim!$A$2:$H$501,2,FALSE) -> Wesley Short | G14: =_xlfn.XLOOKUP(Table1[[#This Row],[Customer_ID]],Customer_Dim!$A$2:$A$501,Customer_Dim!$E$2:$E$501) -> Susanstad | H14: CUST1237 | I14: =VLOOKUP(Table1[[#This Row],[Product_ID]],Product_Dim!$A$2:$G$101,2,FALSE) -> Sports Wrist Sweatbands-Sports | J14: PROD88 | K14: =VLOOKUP(Table1[[#This Row],[Store_ID]],Store_Dim!$A$3:$D$22,2,FALSE) -> Alexander Group-South | L14: STORE4 | M14: 1 | N14: 644.58 | O14: 0.01 | P14: Credit Card | Q14: 2552.5368 | W14: Kurtosis | X14: 0.047375245 | Y14: (+ means Leptokurtic)
A15: SALE13 | B15: ="Q" &ROUNDUP(MONTH(E15)/3,0) -> Q3 | C15: =TEXT(Table1[[#This Row],[Order_Date]],"mmmm") -> August | D15: =YEAR(Table1[[#This Row],[Order_Date]]) -> 2025 | E15: 45875 | F15: =VLOOKUP(Table1[[#This Row],[Customer_ID]],Customer_Dim!$A$2:$H$501,2,FALSE) -> Adam Castro | G15: =_xlfn.XLOOKUP(Table1[[#This Row],[Customer_ID]],Customer_Dim!$A$2:$A$501,Customer_Dim!$E$2:$E$501) -> New Donnabury | H15: CUST1443 | I15: =VLOOKUP(Table1[[#This Row],[Product_ID]],Product_Dim!$A$2:$G$101,2,FALSE) -> Gaming Mechanical Keyboard-Electronics | J15: PROD34 | K15: =VLOOKUP(Table1[[#This Row],[Store_ID]],Store_Dim!$A$3:$D$22,2,FALSE) -> Frederick-Wright-West | L15: STORE16 | M15: 1 | N15: 316.9 | O15: 0.3 | P15: PayPal | Q15: 443.66 | W15: Skewness | X15: 0.8786739 | Y15: (Right Skew for + value)
A16: SALE14 | B16: ="Q" &ROUNDUP(MONTH(E16)/3,0) -> Q2 | C16: =TEXT(Table1[[#This Row],[Order_Date]],"mmmm") -> June | D16: =YEAR(Table1[[#This Row],[Order_Date]]) -> 2025 | E16: 45829 | F16: =VLOOKUP(Table1[[#This Row],[Customer_ID]],Customer_Dim!$A$2:$H$501,2,FALSE) -> Sherry Cabrera | G16: =_xlfn.XLOOKUP(Table1[[#This Row],[Customer_ID]],Customer_Dim!$A$2:$A$501,Customer_Dim!$E$2:$E$501) -> Shannonview | H16: CUST1348 | I16: =VLOOKUP(Table1[[#This Row],[Product_ID]],Product_Dim!$A$2:$G$101,2,FALSE) -> Foldable Camping Chair-Sports | J16: PROD24 | K16: =VLOOKUP(Table1[[#This Row],[Store_ID]],Store_Dim!$A$3:$D$22,2,FALSE) -> Shelton PLC-North | L16: STORE15 | M16: 1 | N16: 403.47 | O16: 0.29 | P16: PayPal | Q16: 1145.8548 | W16: Range | X16: 3889.7838
A17: SALE15 | B17: ="Q" &ROUNDUP(MONTH(E17)/3,0) -> Q4 | C17: =TEXT(Table1[[#This Row],[Order_Date]],"mmmm") -> December | D17: =YEAR(Table1[[#This Row],[Order_Date]]) -> 2024 | E17: 45636 | F17: =VLOOKUP(Table1[[#This Row],[Customer_ID]],Customer_Dim!$A$2:$H$501,2,FALSE) -> Lindsay Beasley | G17: =_xlfn.XLOOKUP(Table1[[#This Row],[Customer_ID]],Customer_Dim!$A$2:$A$501,Customer_Dim!$E$2:$E$501) -> Wesleyhaven | H17: CUST1435 | I17: =VLOOKUP(Table1[[#This Row],[Product_ID]],Product_Dim!$A$2:$G$101,2,FALSE) -> Women's Summer Dress-Clothing | J17: PROD36 | K17: =VLOOKUP(Table1[[#This Row],[Store_ID]],Store_Dim!$A$3:$D$22,2,FALSE) -> Moore, Padilla and Butler-South | L17: STORE9 | M17: 1 | N17: 871.34 | O17: 0.04 | P17: COD | Q17: 2509.4592 | W17: Minimum | X17: 18.459
A18: SALE16 | B18: ="Q" &ROUNDUP(MONTH(E18)/3,0) -> Q3 | C18: =TEXT(Table1[[#This Row],[Order_Date]],"mmmm") -> September | D18: =YEAR(Table1[[#This Row],[Order_Date]]) -> 2025 | E18: 45913 | F18: =VLOOKUP(Table1[[#This Row],[Customer_ID]],Customer_Dim!$A$2:$H$501,2,FALSE) -> Arthur Warren | G18: =_xlfn.XLOOKUP(Table1[[#This Row],[Customer_ID]],Customer_Dim!$A$2:$A$501,Customer_Dim!$E$2:$E$501) -> Ericshire | H18: CUST1276 | I18: =VLOOKUP(Table1[[#This Row],[Product_ID]],Product_Dim!$A$2:$G$101,2,FALSE) -> Adjustable Dumbbells 20kg-Sports | J18: PROD65 | K18: =VLOOKUP(Table1[[#This Row],[Store_ID]],Store_Dim!$A$3:$D$22,2,FALSE) -> Mann-Austin-East | L18: STORE19 | M18: 1 | N18: 451.98 | O18: 0.25 | P18: Credit Card | Q18: 677.97 | W18: Maximum | X18: 3908.2428
A19: SALE17 | B19: ="Q" &ROUNDUP(MONTH(E19)/3,0) -> Q4 | C19: =TEXT(Table1[[#This Row],[Order_Date]],"mmmm") -> December | D19: =YEAR(Table1[[#This Row],[Order_Date]]) -> 2024 | E19: 45637 | F19: =VLOOKUP(Table1[[#This Row],[Customer_ID]],Customer_Dim!$A$2:$H$501,2,FALSE) -> Molly Gardner | G19: =_xlfn.XLOOKUP(Table1[[#This Row],[Customer_ID]],Customer_Dim!$A$2:$A$501,Customer_Dim!$E$2:$E$501) -> Nicoleborough | H19: CUST1079 | I19: =VLOOKUP(Table1[[#This Row],[Product_ID]],Product_Dim!$A$2:$G$101,2,FALSE) -> Decorative Floor Vase-Home | J19: PROD27 | K19: =VLOOKUP(Table1[[#This Row],[Store_ID]],Store_Dim!$A$3:$D$22,2,FALSE) -> Alexander Group-South | L19: STORE4 | M19: 1 | N19: 502.69 | O19: 0.23 | P19: Credit Card | Q19: 774.1426 | W19: Sum | X19: 2175066.6
A20: SALE18 | B20: ="Q" &ROUNDUP(MONTH(E20)/3,0) -> Q3 | C20: =TEXT(Table1[[#This Row],[Order_Date]],"mmmm") -> August | D20: =YEAR(Table1[[#This Row],[Order_Date]]) -> 2024 | E20: 45517 | F20: =VLOOKUP(Table1[[#This Row],[Customer_ID]],Customer_Dim!$A$2:$H$501,2,FALSE) -> David Patterson | G20: =_xlfn.XLOOKUP(Table1[[#This Row],[Customer_ID]],Customer_Dim!$A$2:$A$501,Customer_Dim!$E$2:$E$501) -> New Amyport | H20: CUST1094 | I20: =VLOOKUP(Table1[[#This Row],[Product_ID]],Product_Dim!$A$2:$G$101,2,FALSE) -> Portable Power Bank-Electronics | J20: PROD39 | K20: =VLOOKUP(Table1[[#This Row],[Store_ID]],Store_Dim!$A$3:$D$22,2,FALSE) -> Alexander Group-South | L20: STORE4 | M20: 1 | N20: 559.23 | O20: 0.25 | P20: COD | Q20: 838.845 | W20: Count | X20: 1999
A21: SALE19 | B21: ="Q" &ROUNDUP(MONTH(E21)/3,0) -> Q1 | C21: =TEXT(Table1[[#This Row],[Order_Date]],"mmmm") -> March | D21: =YEAR(Table1[[#This Row],[Order_Date]]) -> 2024 | E21: 45369 | F21: =VLOOKUP(Table1[[#This Row],[Customer_ID]],Customer_Dim!$A$2:$H$501,2,FALSE) -> Maria Hill | G21: =_xlfn.XLOOKUP(Table1[[#This Row],[Customer_ID]],Customer_Dim!$A$2:$A$501,Customer_Dim!$E$2:$E$501) -> Zamoraborough | H21: CUST1239 | I21: =VLOOKUP(Table1[[#This Row],[Product_ID]],Product_Dim!$A$2:$G$101,2,FALSE) -> Luxury Perfume Spray-Beauty | J21: PROD60 | K21: =VLOOKUP(Table1[[#This Row],[Store_ID]],Store_Dim!$A$3:$D$22,2,FALSE) -> Gardner, Humphrey and Contreras-East | L21: STORE13 | M21: 1 | N21: 513.95973 | O21: 0.04 | P21: COD | Q21: 1782.4512
A22: SALE20 | B22: ="Q" &ROUNDUP(MONTH(E22)/3,0) -> Q3 | C22: =TEXT(Table1[[#This Row],[Order_Date]],"mmmm") -> July | D22: =YEAR(Table1[[#This Row],[Order_Date]]) -> 2025 | E22: 45843 | F22: =VLOOKUP(Table1[[#This Row],[Customer_ID]],Customer_Dim!$A$2:$H$501,2,FALSE) -> Justin Cross | G22: =_xlfn.XLOOKUP(Table1[[#This Row],[Customer_ID]],Customer_Dim!$A$2:$A$501,Customer_Dim!$E$2:$E$501) -> North Anthonychester | H22: CUST1144 | I22: =VLOOKUP(Table1[[#This Row],[Product_ID]],Product_Dim!$A$2:$G$101,2,FALSE) -> Professional Jump Rope-Sports | J22: PROD72 | K22: =VLOOKUP(Table1[[#This Row],[Store_ID]],Store_Dim!$A$3:$D$22,2,FALSE) -> Holloway Ltd-North | L22: STORE17 | M22: 1 | N22: 986.04 | O22: 0.27 | P22: COD | Q22: 2159.4276
A23: SALE21 | B23: ="Q" &ROUNDUP(MONTH(E23)/3,0) -> Q2 | C23: =TEXT(Table1[[#This Row],[Order_Date]],"mmmm") -> June | D23: =YEAR(Table1[[#This Row],[Order_Date]]) -> 2024 | E23: 45447 | F23: =VLOOKUP(Table1[[#This Row],[Customer_ID]],Customer_Dim!$A$2:$H$501,2,FALSE) -> Alexander Byrd | G23: =_xlfn.XLOOKUP(Table1[[#This Row],[Customer_ID]],Customer_Dim!$A$2:$A$501,Customer_Dim!$E$2:$E$501) -> Parkerview | H23: CUST1396 | I23: =VLOOKUP(Table1[[#This Row],[Product_ID]],Product_Dim!$A$2:$G$101,2,FALSE) -> USB External Hard Drive-Electronics | J23: PROD43 | K23: =VLOOKUP(Table1[[#This Row],[Store_ID]],Store_Dim!$A$3:$D$22,2,FALSE) -> Guerrero-Schmitt-East | L23: STORE18 | M23: 1 | N23: 589.56 | O23: 0.22 | P23: Credit Card | Q23: 459.8568
A24: SALE22 | B24: ="Q" &ROUNDUP(MONTH(E24)/3,0) -> Q2 | C24: =TEXT(Table1[[#This Row],[Order_Date]],"mmmm") -> April | D24: =YEAR(Table1[[#This Row],[Order_Date]]) -> 2024 | E24: 45394 | F24: =VLOOKUP(Table1[[#This Row],[Customer_ID]],Customer_Dim!$A$2:$H$501,2,FALSE) -> Elizabeth Foster | G24: =_xlfn.XLOOKUP(Table1[[#This Row],[Customer_ID]],Customer_Dim!$A$2:$A$501,Customer_Dim!$E$2:$E$501) -> Anthonymouth | H24: CUST1476 | I24: =VLOOKUP(Table1[[#This Row],[Product_ID]],Product_Dim!$A$2:$G$101,2,FALSE) -> Men's Sports Shorts-Clothing | J24: PROD69 | K24: =VLOOKUP(Table1[[#This Row],[Store_ID]],Store_Dim!$A$3:$D$22,2,FALSE) -> Hill, Wagner and Ballard-East | L24: STORE10 | M24: 1 | N24: 979.42 | O24: 0.03 | P24: PayPal | Q24: 2850.1122
A25: SALE23 | B25: ="Q" &ROUNDUP(MONTH(E25)/3,0) -> Q2 | C25: =TEXT(Table1[[#This Row],[Order_Date]],"mmmm") -> June | D25: =YEAR(Table1[[#This Row],[Order_Date]]) -> 2024 | E25: 45466 | F25: =VLOOKUP(Table1[[#This Row],[Customer_ID]],Customer_Dim!$A$2:$H$501,2,FALSE) -> Miranda King | G25: =_xlfn.XLOOKUP(Table1[[#This Row],[Customer_ID]],Customer_Dim!$A$2:$A$501,Customer_Dim!$E$2:$E$501) -> West Mathew | H25: CUST1368 | I25: =VLOOKUP(Table1[[#This Row],[Product_ID]],Product_Dim!$A$2:$G$101,2,FALSE) -> Hair Strengthening Shampoo-Beauty | J25: PROD12 | K25: =VLOOKUP(Table1[[#This Row],[Store_ID]],Store_Dim!$A$3:$D$22,2,FALSE) -> Bean, Jones and Park-West | L25: STORE8 | M25: 1 | N25: 719.28 | O25: 0.08 | P25: Credit Card | Q25: 661.7376
A26: SALE24 | B26: ="Q" &ROUNDUP(MONTH(E26)/3,0) -> Q3 | C26: =TEXT(Table1[[#This Row],[Order_Date]],"mmmm") -> September | D26: =YEAR(Table1[[#This Row],[Order_Date]]) -> 2025 | E26: 45908 | F26: =VLOOKUP(Table1[[#This Row],[Customer_ID]],Customer_Dim!$A$2:$H$501,2,FALSE) -> Jennifer Pruitt | G26: =_xlfn.XLOOKUP(Table1[[#This Row],[Customer_ID]],Customer_Dim!$A$2:$A$501,Customer_Dim!$E$2:$E$501) -> East Justin | H26: CUST1186 | I26: =VLOOKUP(Table1[[#This Row],[Product_ID]],Product_Dim!$A$2:$G$101,2,FALSE) -> Smart LED Light Strip-Electronics | J26: PROD67 | K26: =VLOOKUP(Table1[[#This Row],[Store_ID]],Store_Dim!$A$3:$D$22,2,FALSE) -> Benson-Elliott-East | L26: STORE6 | M26: 1 | N26: 77.6 | O26: 0.07 | P26: Credit Card | Q26: 216.504
A27: SALE25 | B27: ="Q" &ROUNDUP(MONTH(E27)/3,0) -> Q3 | C27: =TEXT(Table1[[#This Row],[Order_Date]],"mmmm") -> September | D27: =YEAR(Table1[[#This Row],[Order_Date]]) -> 2024 | E27: 45552 | F27: =VLOOKUP(Table1[[#This Row],[Customer_ID]],Customer_Dim!$A$2:$H$501,2,FALSE) -> Erika Padilla | G27: =_xlfn.XLOOKUP(Table1[[#This Row],[Customer_ID]],Customer_Dim!$A$2:$A$501,Customer_Dim!$E$2:$E$501) -> Andrewsland | H27: CUST1381 | I27: =VLOOKUP(Table1[[#This Row],[Product_ID]],Product_Dim!$A$2:$G$101,2,FALSE) -> Men's Leather Belt-Clothing | J27: PROD5 | K27: =VLOOKUP(Table1[[#This Row],[Store_ID]],Store_Dim!$A$3:$D$22,2,FALSE) -> Johnson-Wright-North | L27: STORE3 | M27: 1 | N27: 852.71 | O27: 0.14 | P27: PayPal | Q27: 2933.3224
A28: SALE26 | B28: ="Q" &ROUNDUP(MONTH(E28)/3,0) -> Q1 | C28: =TEXT(Table1[[#This Row],[Order_Date]],"mmmm") -> January | D28: =YEAR(Table1[[#This Row],[Order_Date]]) -> 2024 | E28: 45294 | F28: =VLOOKUP(Table1[[#This Row],[Customer_ID]],Customer_Dim!$A$2:$H$501,2,FALSE) -> Stuart Johnson | G28: =_xlfn.XLOOKUP(Table1[[#This Row],[Customer_ID]],Customer_Dim!$A$2:$A$501,Customer_Dim!$E$2:$E$501) -> West Markport | H28: CUST1213 | I28: =VLOOKUP(Table1[[#This Row],[Product_ID]],Product_Dim!$A$2:$G$101,2,FALSE) -> Portable Bluetooth Speaker-Electronics | J28: PROD98 | K28: =VLOOKUP(Table1[[#This Row],[Store_ID]],Store_Dim!$A$3:$D$22,2,FALSE) -> Bean, Jones and Park-West | L28: STORE8 | M28: 1 | N28: 156.16 | O28: 0.14953799 | P28: Credit Card | Q28: 599.6544
A29: SALE27 | B29: ="Q" &ROUNDUP(MONTH(E29)/3,0) -> Q1 | C29: =TEXT(Table1[[#This Row],[Order_Date]],"mmmm") -> February | D29: =YEAR(Table1[[#This Row],[Order_Date]]) -> 2025 | E29: 45710 | F29: =VLOOKUP(Table1[[#This Row],[Customer_ID]],Customer_Dim!$A$2:$H$501,2,FALSE) -> Anna Perez | G29: =_xlfn.XLOOKUP(Table1[[#This Row],[Customer_ID]],Customer_Dim!$A$2:$A$501,Customer_Dim!$E$2:$E$501) -> South Jerry | H29: CUST1200 | I29: =VLOOKUP(Table1[[#This Row],[Product_ID]],Product_Dim!$A$2:$G$101,2,FALSE) -> WiFi Mesh Router-Electronics | J29: PROD77 | K29: =VLOOKUP(Table1[[#This Row],[Store_ID]],Store_Dim!$A$3:$D$22,2,FALSE) -> Bean, Jones and Park-West | L29: STORE8 | M29: 1 | N29: 815.49 | O29: 0.17 | P29: Credit Card | Q29: 2030.5701
A30: SALE28 | B30: ="Q" &ROUNDUP(MONTH(E30)/3,0) -> Q3 | C30: =TEXT(Table1[[#This Row],[Order_Date]],"mmmm") -> September | D30: =YEAR(Table1[[#This Row],[Order_Date]]) -> 2025 | E30: 45923 | F30: =VLOOKUP(Table1[[#This Row],[Customer_ID]],Customer_Dim!$A$2:$H$501,2,FALSE) -> Theresa Campbell | G30: =_xlfn.XLOOKUP(Table1[[#This Row],[Customer_ID]],Customer_Dim!$A$2:$A$501,Customer_Dim!$E$2:$E$501) -> New Brian | H30: CUST1148 | I30: =VLOOKUP(Table1[[#This Row],[Product_ID]],Product_Dim!$A$2:$G$101,2,FALSE) -> USB-C Fast Charger-Electronics | J30: PROD13 | K30: =VLOOKUP(Table1[[#This Row],[Store_ID]],Store_Dim!$A$3:$D$22,2,FALSE) -> Black-Horn-South | L30: STORE2 | M30: 1 | N30: 74.21 | O30: 0.11 | P30: PayPal | Q30: 132.0938
A31: SALE29 | B31: ="Q" &ROUNDUP(MONTH(E31)/3,0) -> Q1 | C31: =TEXT(Table1[[#This Row],[Order_Date]],"mmmm") -> January | D31: =YEAR(Table1[[#This Row],[Order_Date]]) -> 2024 | E31: 45302 | F31: =VLOOKUP(Table1[[#This Row],[Customer_ID]],Customer_Dim!$A$2:$H$501,2,FALSE) -> Sherry Cabrera | G31: =_xlfn.XLOOKUP(Table1[[#This Row],[Customer_ID]],Customer_Dim!$A$2:$A$501,Customer_Dim!$E$2:$E$501) -> Shannonview | H31: CUST1348 | I31: =VLOOKUP(Table1[[#This Row],[Product_ID]],Product_Dim!$A$2:$G$101,2,FALSE) -> Stainless Steel Cookware Set-Home | J31: PROD99 | K31: =VLOOKUP(Table1[[#This Row],[Store_ID]],Store_Dim!$A$3:$D$22,2,FALSE) -> Johnson-Wright-North | L31: STORE3 | M31: 1 | N31: 451.67 | O31: 0.15 | P31: Credit Card | Q31: 1535.678
A32: SALE30 | B32: ="Q" &ROUNDUP(MONTH(E32)/3,0) -> Q4 | C32: =TEXT(Table1[[#This Row],[Order_Date]],"mmmm") -> October | D32: =YEAR(Table1[[#This Row],[Order_Date]]) -> 2023 | E32: 45217 | F32: =VLOOKUP(Table1[[#This Row],[Customer_ID]],Customer_Dim!$A$2:$H$501,2,FALSE) -> Joshua Ryan | G32: =_xlfn.XLOOKUP(Table1[[#This Row],[Customer_ID]],Customer_Dim!$A$2:$A$501,Customer_Dim!$E$2:$E$501) -> New David | H32: CUST1028 | I32: =VLOOKUP(Table1[[#This Row],[Product_ID]],Product_Dim!$A$2:$G$101,2,FALSE) -> Men's Leather Belt-Clothing | J32: PROD5 | K32: =VLOOKUP(Table1[[#This Row],[Store_ID]],Store_Dim!$A$3:$D$22,2,FALSE) -> Mann-Austin-East | L32: STORE19 | M32: 1 | N32: 429.38 | O32: 0.13 | P32: PayPal | Q32: 373.5606
... A63: SALE61 | B63: ="Q" &ROUNDUP(MONTH(E63)/3,0) -> Q1 | C63: =TEXT(Table1[[#This Row],[Order_Date]],"mmmm") -> February | D63: =YEAR(Table1[[#This Row],[Order_Date]]) -> 2025 | E63: 45716 | F63: =VLOOKUP(Table1[[#This Row],[Customer_ID]],Customer_Dim!$A$2:$H$501,2,FALSE) -> Maria Hill | G63: =_xlfn.XLOOKUP(Table1[[#This Row],[Customer_ID]],Customer_Dim!$A$2:$A$501,Customer_Dim!$E$2:$E$501) -> Zamoraborough | H63: CUST1239 | I63: =VLOOKUP(Table1[[#This Row],[Product_ID]],Product_Dim!$A$2:$G$101,2,FALSE) -> Knee Support Brace-Sports | J63: PROD19 | K63: =VLOOKUP(Table1[[#This Row],[Store_ID]],Store_Dim!$A$3:$D$22,2,FALSE) -> Martinez-Mullins-South | L63: STORE7 | M63: 1 | N63: 374.92 | O63: 0.18 | P63: PayPal | Q63: 307.4344
A64: SALE62 | B64: ="Q" &ROUNDUP(MONTH(E64)/3,0) -> Q3 | C64: =TEXT(Table1[[#This Row],[Order_Date]],"mmmm") -> August | D64: =YEAR(Table1[[#This Row],[Order_Date]]) -> 2024 | E64: 45515 | F64: Unknown | G64: Unknown | H64: CUST1464 | I64: =VLOOKUP(Table1[[#This Row],[Product_ID]],Product_Dim!$A$2:$G$101,2,FALSE) -> USB-C Laptop Charger-Electronics | J64: PROD93 | K64: =VLOOKUP(Table1[[#This Row],[Store_ID]],Store_Dim!$A$3:$D$22,2,FALSE) -> Frederick-Wright-West | L64: STORE16 | M64: 1 | N64: 468.94 | O64: 0.12 | P64: Credit Card | Q64: 412.6672
A65: SALE63 | B65: ="Q" &ROUNDUP(MONTH(E65)/3,0) -> Q3 | C65: =TEXT(Table1[[#This Row],[Order_Date]],"mmmm") -> September | D65: =YEAR(Table1[[#This Row],[Order_Date]]) -> 2025 | E65: 45927 | F65: =VLOOKUP(Table1[[#This Row],[Customer_ID]],Customer_Dim!$A$2:$H$501,2,FALSE) -> James Wolfe | G65: =_xlfn.XLOOKUP(Table1[[#This Row],[Customer_ID]],Customer_Dim!$A$2:$A$501,Customer_Dim!$E$2:$E$501) -> Benjaminton | H65: CUST1126 | I65: =VLOOKUP(Table1[[#This Row],[Product_ID]],Product_Dim!$A$2:$G$101,2,FALSE) -> Face Foundation Kit-Beauty | J65: PROD89 | K65: =VLOOKUP(Table1[[#This Row],[Store_ID]],Store_Dim!$A$3:$D$22,2,FALSE) -> Thomas, Bridges and Harris-North | L65: STORE12 | M65: 1 | N65: 121.37 | O65: 0.05 | P65: Credit Card | Q65: 230.603
A66: SALE64 | B66: ="Q" &ROUNDUP(MONTH(E66)/3,0) -> Q3 | C66: =TEXT(Table1[[#This Row],[Order_Date]],"mmmm") -> September | D66: =YEAR(Table1[[#This Row],[Order_Date]]) -> 2025 | E66: 45914 | F66: =VLOOKUP(Table1[[#This Row],[Customer_ID]],Customer_Dim!$A$2:$H$501,2,FALSE) -> Damon Perez | G66: =_xlfn.XLOOKUP(Table1[[#This Row],[Customer_ID]],Customer_Dim!$A$2:$A$501,Customer_Dim!$E$2:$E$501) -> Jasonton | H66: CUST1255 | I66: =VLOOKUP(Table1[[#This Row],[Product_ID]],Product_Dim!$A$2:$G$101,2,FALSE) -> Men's Track Pants-Clothing | J66: PROD53 | K66: =VLOOKUP(Table1[[#This Row],[Store_ID]],Store_Dim!$A$3:$D$22,2,FALSE) -> Hill, Wagner and Ballard-East | L66: STORE10 | M66: 1 | N66: 480.06 | O66: 0.01 | P66: Credit Card | Q66: 1088.6371
A67: SALE65 | B67: ="Q" &ROUNDUP(MONTH(E67)/3,0) -> Q4 | C67: =TEXT(Table1[[#This Row],[Order_Date]],"mmmm") -> December | D67: =YEAR(Table1[[#This Row],[Order_Date]]) -> 2023 | E67: 45290 | F67: =VLOOKUP(Table1[[#This Row],[Customer_ID]],Customer_Dim!$A$2:$H$501,2,FALSE) -> Mariah Brown | G67: =_xlfn.XLOOKUP(Table1[[#This Row],[Customer_ID]],Customer_Dim!$A$2:$A$501,Customer_Dim!$E$2:$E$501) -> Palmerbury | H67: CUST1162 | I67: =VLOOKUP(Table1[[#This Row],[Product_ID]],Product_Dim!$A$2:$G$101,2,FALSE) -> Stainless Steel Cookware Set-Home | J67: PROD99 | K67: =VLOOKUP(Table1[[#This Row],[Store_ID]],Store_Dim!$A$3:$D$22,2,FALSE) -> Holloway Ltd-North | L67: STORE17 | M67: 1 | N67: 856.57 | O67: 0.24 | P67: Credit Card | Q67: 1301.9864
A68: SALE66 | B68: ="Q" &ROUNDUP(MONTH(E68)/3,0) -> Q4 | C68: =TEXT(Table1[[#This Row],[Order_Date]],"mmmm") -> October | D68: =YEAR(Table1[[#This Row],[Order_Date]]) -> 2023 | E68: 45213 | F68: =VLOOKUP(Table1[[#This Row],[Customer_ID]],Customer_Dim!$A$2:$H$501,2,FALSE) -> Tyrone Olson | G68: =_xlfn.XLOOKUP(Table1[[#This Row],[Customer_ID]],Customer_Dim!$A$2:$A$501,Customer_Dim!$E$2:$E$501) -> Emilytown | H68: CUST1269 | I68: =VLOOKUP(Table1[[#This Row],[Product_ID]],Product_Dim!$A$2:$G$101,2,FALSE) -> WiFi Mesh Router-Electronics | J68: PROD77 | K68: =VLOOKUP(Table1[[#This Row],[Store_ID]],Store_Dim!$A$3:$D$22,2,FALSE) -> Black-Horn-South | L68: STORE2 | M68: 1 | N68: 814.25 | O68: 0.18 | P68: Credit Card | Q68: 2670.74
A69: SALE67 | B69: ="Q" &ROUNDUP(MONTH(E69)/3,0) -> Q4 | C69: =TEXT(Table1[[#This Row],[Order_Date]],"mmmm") -> November | D69: =YEAR(Table1[[#This Row],[Order_Date]]) -> 2023 | E69: 45255 | F69: =VLOOKUP(Table1[[#This Row],[Customer_ID]],Customer_Dim!$A$2:$H$501,2,FALSE) -> Sarah Smith | G69: =_xlfn.XLOOKUP(Table1[[#This Row],[Customer_ID]],Customer_Dim!$A$2:$A$501,Customer_Dim!$E$2:$E$501) -> East Rodney | H69: CUST1483 | I69: =VLOOKUP(Table1[[#This Row],[Product_ID]],Product_Dim!$A$2:$G$101,2,FALSE) -> Hair Strengthening Shampoo-Beauty | J69: PROD12 | K69: =VLOOKUP(Table1[[#This Row],[Store_ID]],Store_Dim!$A$3:$D$22,2,FALSE) -> Black-Horn-South | L69: STORE2 | M69: 1 | N69: 989.17 | O69: 0.2 | P69: PayPal | Q69: 791.336
A70: SALE68 | B70: ="Q" &ROUNDUP(MONTH(E70)/3,0) -> Q4 | C70: =TEXT(Table1[[#This Row],[Order_Date]],"mmmm") -> December | D70: =YEAR(Table1[[#This Row],[Order_Date]]) -> 2023 | E70: 45270 | F70: =VLOOKUP(Table1[[#This Row],[Customer_ID]],Customer_Dim!$A$2:$H$501,2,FALSE) -> Jacqueline Anthony | G70: =_xlfn.XLOOKUP(Table1[[#This Row],[Customer_ID]],Customer_Dim!$A$2:$A$501,Customer_Dim!$E$2:$E$501) -> Vincentside | H70: CUST1372 | I70: =VLOOKUP(Table1[[#This Row],[Product_ID]],Product_Dim!$A$2:$G$101,2,FALSE) -> Professional Jump Rope-Sports | J70: PROD72 | K70: =VLOOKUP(Table1[[#This Row],[Store_ID]],Store_Dim!$A$3:$D$22,2,FALSE) -> Hill, Wagner and Ballard-East | L70: STORE10 | M70: 1 | N70: 62.48 | O70: 0.18 | P70: Credit Card | Q70: 204.9344
...
